Workbook

Sheet Leia-me
A1: Plano do simulador 3D de almoxarifado (SmartStock, RFID, visão computacional)
A3: Ideia central | B3: Separar o cérebro do visual: um motor de simulação calcula tudo e a camada 3D só mostra o que o motor gerou. As tecnologias são módulos que se ligam e desligam no motor.
A4: Abas | B4: Passo a passo: as 10 etapas, com fase, entregável e status. | Módulos: o que cada tecnologia altera e seu custo. | Premissas: parâmetros de efeito (sem x com a tecnologia). | Cenários: as 8 combinações de módulos. | Comparação: resultados lado a lado, com índice de eficiência global. | Indicadores: dicionário de tudo o que medir.
A5: Como usar | B5: Células com fonte azul e fundo amarelo são para você preencher. As demais são fórmulas ou texto fixo. Na aba Comparação, preencha os indicadores com os resultados do simulador; o índice de eficiência, o custo total, a economia, o ROI e o payback calculam sozinhos. Ajuste os pesos (coluna E) para dar mais importância ao que mais interessa.
A6: Atenção aos valores | B6: Os números de efeito e de custo que já estão preenchidos são EXEMPLOS ilustrativos, não dados reais. Substitua por valores de artigos, fornecedores ou de um piloto. Os resultados são tão confiáveis quanto essas premissas.
A7: Ordem recomendada | B7: Faça primeiro a Fase A (motor e comparação em tabela). Só depois a Fase B (3D). Assim a comparação já funciona e o 3D vira uma camada de apresentação, não um risco que trava o projeto.

Sheet Passo a passo
A1: Etapa | B1: Título | C1: O que fazer | D1: Entregável | E1: Ferramenta sugerida | F1: Fase | G1: Ordem recomendada | H1: Status
A2: 1 | B2: Definir o que comparar | C2: Escolher perguntas e indicadores antes de qualquer código. Foco principal em eficiência operacional (tempos, produtividade, distância, erros), mas registrando todos os dados possíveis: serviço, acurácia, estoque, dados do sistema e custos. | D2: Dicionário de indicadores e índice de eficiência (abas Indicadores e Comparação) | E2: Planilha / papel | F2: A - Motor e comparação | G2: 1 | H2: A fazer
A3: 2 | B3: Descrever o almoxarifado como dados | C3: Guardar o layout em um arquivo (JSON): corredores, prateleiras, posições, doca de recebimento e expedição, com coordenadas. O motor usa para distâncias e tempos; o 3D usa o mesmo arquivo para desenhar. | D3: layout.json do almoxarifado | E3: Python + JSON | F3: A - Motor e comparação | G3: 2 | H3: A fazer
A4: 3 | B4: Evoluir o motor para eventos e agentes | C4: Passar do tempo diário para eventos ao longo do dia: pedidos de retirada, operadores que andam até a prateleira, caminhões que chegam e descarregam. O motor diário atual vira o cérebro de reposição dentro dele. | D4: Motor de eventos rodando com operadores e recebimentos | E4: Python + SimPy | F4: A - Motor e comparação | G4: 3 | H4: A fazer
A5: 4 | B5: Separar estoque físico de estoque no sistema | C5: Modelar a divergência: retiradas sem baixa, itens no lugar errado, erros de contagem. Sem isso, RFID e visão computacional não teriam efeito a mostrar. | D5: Duas contagens por item (físico e sistema) e métrica de divergência | E5: Python (motor) | F5: A - Motor e comparação | G5: 4 | H5: A fazer
A6: 5 | B6: Fazer cada tecnologia ser um módulo com liga/desliga | C6: Cada módulo altera parâmetros específicos (aba Módulos e Premissas) e tem custo de implantação e manutenção. | D6: Módulos RFID, Visão e SmartStock configuráveis por arquivo | E6: Python (classes ou plugins) | F6: A - Motor e comparação | G6: 5 | H6: A fazer
A7: 6 | B7: Rodar cenários com a mesma aleatoriedade | C7: Com 3 módulos há 8 combinações. Rodar todas com a mesma semente (mesma demanda e mesmos atrasos) para que a diferença venha só das tecnologias. Guardar os indicadores em tabela. | D7: Tabela de resultados por cenário (aba Comparação) | E7: Python + pandas | F7: A - Motor e comparação | G7: 6 | H7: A fazer
A8: 7 | B8: Gerar um registro de eventos | C8: Gravar o que aconteceu durante a simulação (ex.: às 09:12 o operador 2 saiu da doca e foi para a posição B-14). Esse arquivo é a ponte para o 3D. | D8: events.json ou CSV com carimbo de tempo | E8: Python | F8: B - Visualização 3D | G8: 8 | H8: A fazer
A9: 8 | B9: Construir a visualização 3D | C9: Página web com prateleiras como caixas, operadores como pontos que se movem, cor da prateleira conforme o nível de estoque, e ícones/efeitos para RFID e câmeras. Reproduz o registro de eventos como um filme, com controle de velocidade. Começar com cubos coloridos. | D9: Página 3D que reproduz a simulação | E9: Three.js ou react-three-fiber (alternativas: Unity, Godot) | F9: B - Visualização 3D | G9: 9 | H9: A fazer
A10: 9 | B10: Montar a interface de comparação | C10: Painel com interruptores (RFID, visão, SmartStock), sliders de parâmetros e, ao lado do 3D, os indicadores. Ideal: dois cenários lado a lado mostrando a diferença nos números. | D10: Painel interativo com cenários lado a lado | E10: Streamlit ou a própria página web | F10: B - Visualização 3D | G10: 10 | H10: A fazer
A11: 10 | B11: Validar e calibrar | C11: Comparar o cenário sem nada com o que se sabe do almoxarifado real (taxa de ruptura, tempo médio de separação). Se a base não reproduz a realidade atual, os ganhos simulados não servem de argumento. | D11: Relatório de calibração do cenário base | E11: Dados reais + planilha | F11: A - Motor e comparação | G11: 7 | H11: A fazer
A13: Etapas concluídas: | C13: =COUNTIF(H2:H11,"Concluído")&" de "&COUNTA(A2:A11)

Sheet Módulos
A1: Módulos de tecnologia: o que alteram e quanto custam
A2: Valores de custo em fonte azul/fundo amarelo são EXEMPLOS: substitua por orçamentos reais.
A4: Módulo | B4: O que altera na simulação | C4: Custo de implantação (R$) | D4: Vida útil (anos) | E4: Manutenção (R$/ano) | F4: Custo anualizado (R$/ano) | G4: Observação
A5: RFID | B5: Reduz a divergência de inventário, acelera recebimento e contagem, localiza itens. | C5: 150000 | D5: 5 | E5: 12000 | F5: =IF(D5>0,C5/D5,0)+E5 | G5: Exemplo: etiquetas, leitores/portais e integração.
A6: Visão computacional | B6: Detecta retiradas e ocupação de prateleira, reduz erros de separação. | C6: 90000 | D6: 4 | E6: 9000 | F6: =IF(D6>0,C6/D6,0)+E6 | G6: Exemplo: câmeras, processamento e licença do software.
A7: SmartStock | B7: Troca a política de reposição (min/max fixo por adaptativa). | C7: 30000 | D7: 3 | E7: 6000 | F7: =IF(D7>0,C7/D7,0)+E7 | G7: Exemplo: desenvolvimento, integração e suporte.
A8: Total (todos os módulos) | C8: =SUM(C5:C7) | E8: =SUM(E5:E7) | F8: =SUM(F5:F7)

Sheet Premissas
A1: Parâmetros de efeito: valor sem x com a tecnologia
A2: EXEMPLOS ilustrativos. Substitua por dados de artigos, fornecedores ou piloto, e registre a fonte.
A4: Módulo | B4: Parâmetro | C4: Unidade | D4: Sem a tecnologia | E4: Com a tecnologia | F4: Redução relativa | G4: Fonte / observação
A5: RFID | B5: Divergência de inventário (sistema x prateleira) | C5: % dos itens | D5: 0.08 | E5: 0.01 | F5: =IF(D5=0,0,(D5-E5)/D5) | G5: Exemplo, definir com dados reais
A6: RFID | B6: Tempo de recebimento por lote | C6: min | D6: 45 | E6: 15 | F6: =IF(D6=0,0,(D6-E6)/D6) | G6: Exemplo, definir com dados reais
A7: RFID | B7: Tempo de contagem cíclica por item | C7: s | D7: 30 | E7: 5 | F7: =IF(D7=0,0,(D7-E7)/D7) | G7: Exemplo, definir com dados reais
A8: Visão computacional | B8: Erro de separação (item errado) | C8: % dos pedidos | D8: 0.03 | E8: 0.005 | F8: =IF(D8=0,0,(D8-E8)/D8) | G8: Exemplo, definir com dados reais
A9: Visão computacional | B9: Retiradas sem baixa no sistema | C9: % das retiradas | D9: 0.05 | E9: 0.01 | F9: =IF(D9=0,0,(D9-E9)/D9) | G9: Exemplo, definir com dados reais
A10: SmartStock | B10: Nível de serviço alvo da reposição | C10: % da demanda | D10: 0.94 | E10: 0.97 | F10: =IF(D10=0,0,(D10-E10)/D10) | G10: Política min/max atual x alvo do SmartStock (simulação)
A12: Nota: a redução relativa de 'Nível de serviço' é negativa porque o valor sobe com a tecnologia; leia o sinal como melhora.

Sheet Cenários
A1: Cenários: 8 combinações de módulos (mesma semente aleatória em todos)
A2: 1 = tecnologia ligada, 0 = desligada. Os resultados de cada cenário ficam na aba Comparação.
A4: Cenário | B4: RFID | C4: Visão comp. | D4: SmartStock | E4: Custo anual das tecnologias (R$/ano) | F4: Investimento inicial (R$)
A5: Base (nada) | B5: 0 | C5: 0 | D5: 0 | E5: =B5*Módulos!$F$5+C5*Módulos!$F$6+D5*Módulos!$F$7 | F5: =B5*Módulos!$C$5+C5*Módulos!$C$6+D5*Módulos!$C$7
A6: Só RFID | B6: 1 | C6: 0 | D6: 0 | E6: =B6*Módulos!$F$5+C6*Módulos!$F$6+D6*Módulos!$F$7 | F6: =B6*Módulos!$C$5+C6*Módulos!$C$6+D6*Módulos!$C$7
A7: Só visão computacional | B7: 0 | C7: 1 | D7: 0 | E7: =B7*Módulos!$F$5+C7*Módulos!$F$6+D7*Módulos!$F$7 | F7: =B7*Módulos!$C$5+C7*Módulos!$C$6+D7*Módulos!$C$7
A8: Só SmartStock | B8: 0 | C8: 0 | D8: 1 | E8: =B8*Módulos!$F$5+C8*Módulos!$F$6+D8*Módulos!$F$7 | F8: =B8*Módulos!$C$5+C8*Módulos!$C$6+D8*Módulos!$C$7
A9: RFID + visão | B9: 1 | C9: 1 | D9: 0 | E9: =B9*Módulos!$F$5+C9*Módulos!$F$6+D9*Módulos!$F$7 | F9: =B9*Módulos!$C$5+C9*Módulos!$C$6+D9*Módulos!$C$7
A10: RFID + SmartStock | B10: 1 | C10: 0 | D10: 1 | E10: =B10*Módulos!$F$5+C10*Módulos!$F$6+D10*Módulos!$F$7 | F10: =B10*Módulos!$C$5+C10*Módulos!$C$6+D10*Módulos!$C$7
A11: Visão + SmartStock | B11: 0 | C11: 1 | D11: 1 | E11: =B11*Módulos!$F$5+C11*Módulos!$F$6+D11*Módulos!$F$7 | F11: =B11*Módulos!$C$5+C11*Módulos!$C$6+D11*Módulos!$C$7
A12: Todos | B12: 1 | C12: 1 | D12: 1 | E12: =B12*Módulos!$F$5+C12*Módulos!$F$6+D12*Módulos!$F$7 | F12: =B12*Módulos!$C$5+C12*Módulos!$C$6+D12*Módulos!$C$7

Sheet Comparação
A1: Comparação dos 8 cenários (foco em eficiência)
A2: Preencha as células amarelas com os resultados do simulador. Verde = melhor valor da linha. O índice de eficiência usa os pesos da coluna E e vale 100 no cenário base.
A4: Indicador | B4: Unidade | C4: Melhor quando | D4: Prioridade | E4: Peso no índice | F4: =Cenários!A5 | G4: =Cenários!A6 | H4: =Cenários!A7 | I4: =Cenários!A8 | J4: =Cenários!A9 | K4: =Cenários!A10 | L4: =Cenários!A11 | M4: =Cenários!A12 | N4: Melhor cenário | O4: Variação do melhor vs. base
A5: ÍNDICE DE EFICIÊNCIA GLOBAL (base = 100) | B5: pontos | C5: Maior | D5: Principal | F5: =IF(F59=0,"",SUMPRODUCT($E$50:$E$58,F50:F58)/F59*100) | G5: =IF(G59=0,"",SUMPRODUCT($E$50:$E$58,G50:G58)/G59*100) | H5: =IF(H59=0,"",SUMPRODUCT($E$50:$E$58,H50:H58)/H59*100) | I5: =IF(I59=0,"",SUMPRODUCT($E$50:$E$58,I50:I58)/I59*100) | J5: =IF(J59=0,"",SUMPRODUCT($E$50:$E$58,J50:J58)/J59*100) | K5: =IF(K59=0,"",SUMPRODUCT($E$50:$E$58,K50:K58)/K59*100) | L5: =IF(L59=0,"",SUMPRODUCT($E$50:$E$58,L50:L58)/L59*100) | M5: =IF(M59=0,"",SUMPRODUCT($E$50:$E$58,M50:M58)/M59*100) | N5: =IF(COUNT(F5:M5)=0,"",INDEX($F$4:$M$4,MATCH(MAX(F5:M5),F5:M5,0))) | O5: =IF(OR(N5="",F5=""),"",(MAX(F5:M5)-F5)/F5)
A7: 1. Eficiência operacional (principal)
A8: Tempo médio de separação por pedido | B8: min | C8: Menor | D8: Principal | E8: 3 | F8: 2.2769 | G8: 2.3001 | H8: 2.0011 | I8: 2.2793 | J8: 2.0077 | K8: 2.3022 | L8: 2.0013 | M8: 2.007 | N8: =IF(COUNT(F8:M8)=0,"",INDEX($F$4:$M$4,MATCH(MIN(F8:M8),F8:M8,0))) | O8: =IF(OR(N8="",F8="",F8=0),"",(MIN(F8:M8)-F8)/ABS(F8))
A9: Produtividade (pedidos por operador-hora) | B9: pedidos/h | C9: Maior | D9: Principal | E9: 3 | F9: 26.3516 | G9: 26.0856 | H9: 29.9828 | I9: 26.3239 | J9: 29.8852 | K9: 26.0623 | L9: 29.9805 | M9: 29.8961 | N9: =IF(COUNT(F9:M9)=0,"",INDEX($F$4:$M$4,MATCH(MAX(F9:M9),F9:M9,0))) | O9: =IF(OR(N9="",F9="",F9=0),"",(MAX(F9:M9)-F9)/ABS(F9))
A10: Tempo de ciclo do pedido (do pedido à expedição) | B10: h | C10: Menor | D10: Principal | E10: 2 | F10: 0.095 | G10: 0.0423 | H10: 0.0883 | I10: 0.0705 | J10: 0.0367 | K10: 0.0411 | L10: 0.0595 | M10: 0.0356 | N10: =IF(COUNT(F10:M10)=0,"",INDEX($F$4:$M$4,MATCH(MIN(F10:M10),F10:M10,0))) | O10: =IF(OR(N10="",F10="",F10=0),"",(MIN(F10:M10)-F10)/ABS(F10))
A11: Distância percorrida por pedido | B11: m | C11: Menor | D11: Principal | E11: 1 | F11: 46.4909 | G11: 46.4782 | H11: 45.1332 | I11: 46.3091 | J11: 44.7667 | K11: 46.3128 | L11: 44.8813 | M11: 44.4982 | N11: =IF(COUNT(F11:M11)=0,"",INDEX($F$4:$M$4,MATCH(MIN(F11:M11),F11:M11,0))) | O11: =IF(OR(N11="",F11="",F11=0),"",(MIN(F11:M11)-F11)/ABS(F11))
A12: Tempo gasto procurando itens | B12: min/dia | C12: Menor | D12: Principal | E12: 1 | F12: 0.2082 | G12: 0.0027 | H12: 0.2521 | I12: 0.263 | J12: 0.0046 | K12: 0.0018 | L12: 0.2411 | M12: 0.0027 | N12: =IF(COUNT(F12:M12)=0,"",INDEX($F$4:$M$4,MATCH(MIN(F12:M12),F12:M12,0))) | O12: =IF(OR(N12="",F12="",F12=0),"",(MIN(F12:M12)-F12)/ABS(F12))
A13: Tempo de recebimento por lote | B13: min | C13: Menor | D13: Principal | E13: 2 | F13: 46.5135 | G13: 16.5223 | H13: 46.5314 | I13: 46.5204 | J13: 16.5461 | K13: 16.5243 | L13: 46.5394 | M13: 16.5478 | N13: =IF(COUNT(F13:M13)=0,"",INDEX($F$4:$M$4,MATCH(MIN(F13:M13),F13:M13,0))) | O13: =IF(OR(N13="",F13="",F13=0),"",(MIN(F13:M13)-F13)/ABS(F13))
A14: Tempo de inventário e contagem cíclica | B14: h/mês | C14: Menor | D14: Principal | E14: 2 | F14: 1.6955 | G14: 0.625 | H14: 1.7429 | I14: 1.6857 | J14: 0.625 | K14: 0.625 | L14: 1.6857 | M14: 0.625 | N14: =IF(COUNT(F14:M14)=0,"",INDEX($F$4:$M$4,MATCH(MIN(F14:M14),F14:M14,0))) | O14: =IF(OR(N14="",F14="",F14=0),"",(MIN(F14:M14)-F14)/ABS(F14))
A15: Taxa de erro de separação | B15: % dos pedidos | C15: Menor | D15: Principal | E15: 2 | F15: 0.0618 | G15: 0.0619 | H15: 0.0102 | I15: 0.0652 | J15: 0.0103 | K15: 0.0654 | L15: 0.0108 | M15: 0.0108 | N15: =IF(COUNT(F15:M15)=0,"",INDEX($F$4:$M$4,MATCH(MIN(F15:M15),F15:M15,0))) | O15: =IF(OR(N15="",F15="",F15=0),"",(MIN(F15:M15)-F15)/ABS(F15))
A16: Retrabalho e correções internas | B16: % dos pedidos | C16: Menor | D16: Principal | E16: 1 | F16: 0.0435 | G16: 0.0548 | H16: 0.0004 | I16: 0.0459 | J16: 0.0005 | K16: 0.0579 | L16: 0.0006 | M16: 0.0006 | N16: =IF(COUNT(F16:M16)=0,"",INDEX($F$4:$M$4,MATCH(MIN(F16:M16),F16:M16,0))) | O16: =IF(OR(N16="",F16="",F16=0),"",(MIN(F16:M16)-F16)/ABS(F16))
A17: Utilização dos operadores | B17: % do tempo | C17: Informativo | D17: Principal | F17: 0.2824 | G17: 0.1821 | H17: 0.2692 | I17: 0.2384 | J17: 0.1658 | K17: 0.1656 | L17: 0.2232 | M17: 0.1497
A18: 2. Nível de serviço
A19: Nível de serviço (fill rate) | B19: % da demanda | C19: Maior | D19: Complementar | F19: 0.9262 | G19: 0.9281 | H19: 0.9277 | I19: 0.9912 | J19: 0.9275 | K19: 0.9913 | L19: 0.9912 | M19: 0.9919 | N19: =IF(COUNT(F19:M19)=0,"",INDEX($F$4:$M$4,MATCH(MAX(F19:M19),F19:M19,0))) | O19: =IF(OR(N19="",F19="",F19=0),"",(MAX(F19:M19)-F19)/ABS(F19))
A20: Pedidos completos e no prazo (OTIF) | B20: % dos pedidos | C20: Maior | D20: Complementar | F20: 0.8232 | G20: 0.8381 | H20: 0.8423 | I20: 0.959 | J20: 0.8431 | K20: 0.9717 | L20: 0.9789 | M20: 0.9805 | N20: =IF(COUNT(F20:M20)=0,"",INDEX($F$4:$M$4,MATCH(MAX(F20:M20),F20:M20,0))) | O20: =IF(OR(N20="",F20="",F20=0),"",(MAX(F20:M20)-F20)/ABS(F20))
A21: Dias de ruptura | B21: dias | C21: Menor | D21: Complementar | F21: 983 | G21: 946 | H21: 961 | I21: 162 | J21: 941 | K21: 133 | L21: 152 | M21: 133 | N21: =IF(COUNT(F21:M21)=0,"",INDEX($F$4:$M$4,MATCH(MIN(F21:M21),F21:M21,0))) | O21: =IF(OR(N21="",F21="",F21=0),"",(MIN(F21:M21)-F21)/ABS(F21))
A22: Itens com ruptura | B22: % dos itens | C22: Menor | D22: Complementar | F22: 0.9833 | G22: 0.9667 | H22: 0.9667 | I22: 0.75 | J22: 0.9667 | K22: 0.7167 | L22: 0.75 | M22: 0.7167 | N22: =IF(COUNT(F22:M22)=0,"",INDEX($F$4:$M$4,MATCH(MIN(F22:M22),F22:M22,0))) | O22: =IF(OR(N22="",F22="",F22=0),"",(MIN(F22:M22)-F22)/ABS(F22))
A23: 3. Acurácia do inventário
A24: Divergência de inventário | B24: % dos itens | C24: Menor | D24: Complementar | F24: 0.4316 | G24: 0.0962 | H24: 0.1365 | I24: 0.4457 | J24: 0.0521 | K24: 0.0999 | L24: 0.1411 | M24: 0.0547 | N24: =IF(COUNT(F24:M24)=0,"",INDEX($F$4:$M$4,MATCH(MIN(F24:M24),F24:M24,0))) | O24: =IF(OR(N24="",F24="",F24=0),"",(MIN(F24:M24)-F24)/ABS(F24))
A25: Acurácia de localização | B25: % dos itens | C25: Maior | D25: Complementar | F25: 0.9989 | G25: 0.9999 | H25: 0.9989 | I25: 0.9989 | J25: 0.9997 | K25: 1 | L25: 0.999 | M25: 1 | N25: =IF(COUNT(F25:M25)=0,"",INDEX($F$4:$M$4,MATCH(MAX(F25:M25),F25:M25,0))) | O25: =IF(OR(N25="",F25="",F25=0),"",(MAX(F25:M25)-F25)/ABS(F25))
A26: Estoque fantasma | B26: R$ | C26: Menor | D26: Complementar | F26: 1795.0048 | G26: 254.6132 | H26: 383.8764 | I26: 1962.6041 | J26: 122.0371 | K26: 269.667 | L26: 423.8799 | M26: 128.5576 | N26: =IF(COUNT(F26:M26)=0,"",INDEX($F$4:$M$4,MATCH(MIN(F26:M26),F26:M26,0))) | O26: =IF(OR(N26="",F26="",F26=0),"",(MIN(F26:M26)-F26)/ABS(F26))
A27: Perdas, avarias e extravios | B27: R$/ano | C27: Menor | D27: Complementar | F27: 2722.23 | G27: 0 | H27: 3046.68 | I27: 5446.28 | J27: 0 | K27: 0 | L27: 4345.98 | M27: 0 | N27: =IF(COUNT(F27:M27)=0,"",INDEX($F$4:$M$4,MATCH(MIN(F27:M27),F27:M27,0))) | O27: =IF(OR(N27="",F27="",F27=0),"",(MIN(F27:M27)-F27)/ABS(F27))
A28: 4. Estoque e reposição
A29: Estoque médio | B29: R$ | C29: Menor | D29: Complementar | F29: 73851.458 | G29: 74780.27 | H29: 74817.935 | I29: 127096.41 | J29: 75052.386 | K29: 129787.85 | L29: 129403.73 | M29: 130090.57 | N29: =IF(COUNT(F29:M29)=0,"",INDEX($F$4:$M$4,MATCH(MIN(F29:M29),F29:M29,0))) | O29: =IF(OR(N29="",F29="",F29=0),"",(MIN(F29:M29)-F29)/ABS(F29))
A30: Giro anual | B30: vezes/ano | C30: Maior | D30: Complementar | F30: 26.3998 | G30: 26.1414 | H30: 26.1129 | I30: 16.3195 | J30: 26.0352 | K30: 15.9847 | L30: 16.0291 | M30: 15.9518 | N30: =IF(COUNT(F30:M30)=0,"",INDEX($F$4:$M$4,MATCH(MAX(F30:M30),F30:M30,0))) | O30: =IF(OR(N30="",F30="",F30=0),"",(MAX(F30:M30)-F30)/ABS(F30))
A31: Cobertura média de estoque | B31: dias | C31: Informativo | D31: Complementar | F31: 12.1922 | G31: 12.3417 | H31: 12.3761 | I31: 21.2096 | J31: 12.3986 | K31: 21.7605 | L31: 21.6366 | M31: 21.8214
A32: Pedidos de compra emitidos | B32: pedidos/ano | C32: Menor | D32: Complementar | F32: 1359 | G32: 1380 | H32: 1372 | I32: 973 | J32: 1366 | K32: 971 | L32: 974 | M32: 972 | N32: =IF(COUNT(F32:M32)=0,"",INDEX($F$4:$M$4,MATCH(MIN(F32:M32),F32:M32,0))) | O32: =IF(OR(N32="",F32="",F32=0),"",(MIN(F32:M32)-F32)/ABS(F32))
A33: Compras emergenciais | B33: pedidos/ano | C33: Menor | D33: Complementar | F33: 40 | G33: 33 | H33: 33 | I33: 12 | J33: 33 | K33: 8 | L33: 10 | M33: 11 | N33: =IF(COUNT(F33:M33)=0,"",INDEX($F$4:$M$4,MATCH(MIN(F33:M33),F33:M33,0))) | O33: =IF(OR(N33="",F33="",F33=0),"",(MIN(F33:M33)-F33)/ABS(F33))
A34: Itens parados (sem saída há 90 dias) | B34: % dos itens | C34: Menor | D34: Complementar | F34: 0 | G34: 0 | H34: 0 | I34: 0 | J34: 0 | K34: 0 | L34: 0 | M34: 0 | N34: =IF(COUNT(F34:M34)=0,"",INDEX($F$4:$M$4,MATCH(MIN(F34:M34),F34:M34,0))) | O34: =IF(OR(N34="",F34="",F34=0),"",(MIN(F34:M34)-F34)/ABS(F34))
A35: Ocupação do espaço | B35: % das posições | C35: Informativo | D35: Complementar | F35: 0.4686 | G35: 0.47 | H35: 0.47 | I35: 0.4961 | J35: 0.4697 | K35: 0.4964 | L35: 0.4962 | M35: 0.4963
A36: 5. Dados e sistema
A37: Latência da informação | B37: min | C37: Menor | D37: Complementar | F37: 341.2863 | G37: 18.5621 | H37: 44.3165 | I37: 342.043 | J37: 2.9827 | K37: 18.7084 | L37: 41.5739 | M37: 2.8911 | N37: =IF(COUNT(F37:M37)=0,"",INDEX($F$4:$M$4,MATCH(MIN(F37:M37),F37:M37,0))) | O37: =IF(OR(N37="",F37="",F37=0),"",(MIN(F37:M37)-F37)/ABS(F37))
A38: Cobertura de rastreamento | B38: % dos movimentos | C38: Maior | D38: Complementar | F38: 0 | G38: 0.9499 | H38: 0.8736 | I38: 0 | J38: 0.9943 | K38: 0.9493 | L38: 0.882 | M38: 0.9946 | N38: =IF(COUNT(F38:M38)=0,"",INDEX($F$4:$M$4,MATCH(MAX(F38:M38),F38:M38,0))) | O38: =IF(OR(N38="",F38="",F38=0),"",(MAX(F38:M38)-F38)/ABS(F38))
A39: Alertas falsos | B39: alertas/semana | C39: Menor | D39: Complementar | F39: 0 | G39: 3.5863 | H39: 6.8466 | I39: 0 | J39: 10.3945 | K39: 3.7014 | L39: 7.1151 | M39: 10.7781 | N39: =IF(COUNT(F39:M39)=0,"",INDEX($F$4:$M$4,MATCH(MIN(F39:M39),F39:M39,0))) | O39: =IF(OR(N39="",F39="",F39=0),"",(MIN(F39:M39)-F39)/ABS(F39))
A40: 6. Custos e retorno
A41: Custo operacional anual (sem tecnologias) | B41: R$/ano | C41: Menor | D41: Complementar | F41: 259493.61 | G41: 234987.91 | H41: 256284.01 | I41: 173153.34 | J41: 230948.15 | K41: 152673.8 | L41: 169464.92 | M41: 149201.42 | N41: =IF(COUNT(F41:M41)=0,"",INDEX($F$4:$M$4,MATCH(MIN(F41:M41),F41:M41,0))) | O41: =IF(OR(N41="",F41="",F41=0),"",(MIN(F41:M41)-F41)/ABS(F41))
A42: Custo anual das tecnologias | B42: R$/ano | C42: Informativo | D42: Complementar | F42: =Cenários!E5 | G42: =Cenários!E6 | H42: =Cenários!E7 | I42: =Cenários!E8 | J42: =Cenários!E9 | K42: =Cenários!E10 | L42: =Cenários!E11 | M42: =Cenários!E12
...

Sheet Indicadores
A1: Dicionário de indicadores (foco em eficiência, com todos os dados possíveis)
A3: Grupo | B3: Indicador | C3: Definição | D3: Unidade | E3: Melhor quando | F3: Prioridade | G3: Como medir na simulação | H3: Módulo que mais influencia | I3: Exemplo de valor
A4: 1. Eficiência operacional (principal) | B4: Tempo médio de separação por pedido | C4: Tempo do início ao fim da separação de um pedido. | D4: min | E4: Menor | F4: Principal | G4: Média dos tempos dos operadores no motor de eventos. | H4: RFID, Visão | I4: 6.5
A5: 1. Eficiência operacional (principal) | B5: Produtividade (pedidos por operador-hora) | C5: Pedidos concluídos divididos pelas horas de trabalho dos operadores. | D5: pedidos/h | E5: Maior | F5: Principal | G5: Pedidos concluídos / horas de operador. | H5: RFID, Visão | I5: 12
A6: 1. Eficiência operacional (principal) | B6: Tempo de ciclo do pedido (do pedido à expedição) | C6: Tempo total desde a chegada do pedido até a expedição. | D6: h | E6: Menor | F6: Principal | G6: Carimbos de tempo no registro de eventos. | H6: RFID, Visão | I6: 4.2
A7: 1. Eficiência operacional (principal) | B7: Distância percorrida por pedido | C7: Caminho médio percorrido pelo operador para separar um pedido. | D7: m | E7: Menor | F7: Principal | G7: Soma das distâncias no layout (passo 2). | H7: RFID | I7: 85
A8: 1. Eficiência operacional (principal) | B8: Tempo gasto procurando itens | C8: Tempo diário por operador gasto localizando itens. | D8: min/dia | E8: Menor | F8: Principal | G8: Tempo de busca nos eventos de separação. | H8: RFID | I8: 35
A9: 1. Eficiência operacional (principal) | B9: Tempo de recebimento por lote | C9: Tempo para conferir e guardar um lote recebido. | D9: min | E9: Menor | F9: Principal | G9: Duração do evento de recebimento. | H9: RFID | I9: 15
A10: 1. Eficiência operacional (principal) | B10: Tempo de inventário e contagem cíclica | C10: Horas por mês dedicadas a contar estoque. | D10: h/mês | E10: Menor | F10: Principal | G10: Duração dos eventos de contagem. | H10: RFID, Visão | I10: 20
A11: 1. Eficiência operacional (principal) | B11: Taxa de erro de separação | C11: Pedidos separados com item ou quantidade errada. | D11: % dos pedidos | E11: Menor | F11: Principal | G11: Pedidos com erro / pedidos separados. | H11: Visão | I11: 0.005
A12: 1. Eficiência operacional (principal) | B12: Retrabalho e correções internas | C12: Pedidos que precisaram ser refeitos ou corrigidos. | D12: % dos pedidos | E12: Menor | F12: Principal | G12: Pedidos refeitos / pedidos separados. | H12: Visão, RFID | I12: 0.01
A13: 1. Eficiência operacional (principal) | B13: Utilização dos operadores | C13: Parcela do tempo em que os operadores estão ocupados (muito alta indica gargalo, muito baixa indica ociosidade). | D13: % do tempo | E13: Informativo | F13: Principal | G13: Horas ocupadas / horas disponíveis. | H13: Todos | I13: 0.72
A14: 2. Nível de serviço | B14: Nível de serviço (fill rate) | C14: Parcela da demanda atendida sem falta. | D14: % da demanda | E14: Maior | F14: Complementar | G14: Vendido total / demanda total. | H14: SmartStock | I14: 0.985
A15: 2. Nível de serviço | B15: Pedidos completos e no prazo (OTIF) | C15: Parcela dos pedidos atendidos completos e dentro do prazo. | D15: % dos pedidos | E15: Maior | F15: Complementar | G15: Pedidos completos no prazo / total de pedidos. | H15: SmartStock, RFID | I15: 0.95
... A32: 6. Custos e retorno | B32: Custo operacional anual (sem tecnologias) | C32: Mão de obra, posse de estoque, pedidos e ruptura. | D32: R$/ano | E32: Menor | F32: Complementar | G32: Soma dos componentes de custo do simulador. | H32: Todos | I32: 410000
A33: 6. Custos e retorno | B33: Custo anual das tecnologias | C33: Implantação anualizada mais manutenção dos módulos ligados. | D33: R$/ano | E33: Informativo | F33: Complementar | G33: Calculado a partir das abas Módulos e Cenários. | H33: - | I33: calculado
A34: 6. Custos e retorno | B34: Custo total anual | C34: Custo operacional mais custo das tecnologias. | D34: R$/ano | E34: Menor | F34: Complementar | G34: Calculado. | H34: Todos | I34: calculado
A35: 6. Custos e retorno | B35: Economia anual vs. base | C35: Custo total do cenário base menos o custo total do cenário. | D35: R$/ano | E35: Maior | F35: Complementar | G35: Calculado. | H35: Todos | I35: calculado
A36: 6. Custos e retorno | B36: Investimento inicial | C36: Implantação dos módulos ligados. | D36: R$ | E36: Informativo | F36: Complementar | G36: Calculado a partir das abas Módulos e Cenários. | H36: - | I36: calculado
A37: 6. Custos e retorno | B37: Retorno do investimento (ROI anual) | C37: Economia anual dividida pelo investimento inicial. | D37: % ao ano | E37: Maior | F37: Complementar | G37: Calculado. | H37: Todos | I37: calculado
A38: 6. Custos e retorno | B38: Payback | C38: Meses para a economia pagar o investimento. | D38: meses | E38: Menor | F38: Complementar | G38: Calculado. | H38: Todos | I38: calculado
A40: Os exemplos de valor mostram apenas o formato esperado; não são dados reais.
